<sdf version='1.7'>
  <model name='anymal'>
    <link name='base'>
      <inertial>
        <pose>-0.001961 -0.001413 0.050207 0 -0 0</pose>
        <mass>16.7935</mass>
        <inertia>
          <ixx>0.217391</ixx>
          <ixy>-0.00132873</ixy>
          <ixz>-0.002282</ixz>
          <iyy>0.639433</iyy>
          <iyz>-0.00138078</iyz>
          <izz>0.624141</izz>
        </inertia>
      </inertial>
      <collision name='base_collision'>
        <pose>0 0 0.08 0 -0 0</pose>
        <geometry>
          <box>
            <size>0.531 0.27 0.24</size>
          </box>
        </geometry>
      </collision>
      <collision name='base_collision_1'>
        <pose>0.227 0.116 0 0 1.5708 0</pose>
        <geometry>
          <cylinder>
            <length>0.1</length>
            <radius>0.05</radius>
          </cylinder>
        </geometry>
      </collision>
      <collision name='base_collision_2'>
        <pose>0.227 -0.116 0 0 1.5708 0</pose>
        <geometry>
          <cylinder>
            <length>0.1</length>
            <radius>0.05</radius>
          </cylinder>
        </geometry>
      </collision>
      <collision name='base_collision_3'>
        <pose>-0.227 0.116 0 0 1.5708 0</pose>
        <geometry>
          <cylinder>
            <length>0.1</length>
            <radius>0.05</radius>
          </cylinder>
        </geometry>
      </collision>
      <collision name='base_collision_4'>
        <pose>-0.227 -0.116 0 0 1.5708 0</pose>
        <geometry>
          <cylinder>
            <length>0.1</length>
            <radius>0.05</radius>
          </cylinder>
        </geometry>
      </collision>
      <collision name='base_collision_5'>
        <pose>0.2155 0 -0.09 0 -0 0</pose>
        <geometry>
          <box>
            <size>0.1 0.1 0.07</size>
          </box>
        </geometry>
      </collision>
      <collision name='base_collision_6'>
        <pose>-0.2155 0 -0.09 0 -0 0</pose>
        <geometry>
          <box>
            <size>0.1 0.1 0.07</size>
          </box>
        </geometry>
      </collision>
      <collision name='base_collision_7'>
        <pose>0 0 -0.09 0 -0 0</pose>
        <geometry>
          <box>
            <size>0.531 0.02 0.07</size>
          </box>
        </geometry>
      </collision>
      <visual name='base_visual'>
        <pose>0 0 0 0 -0 0</pose>
        <geometry>
          <mesh>
            <scale>0.001 0.001 0.001</scale>
            <uri>model://anymal_b_simple_description/meshes/anymal_base.dae</uri>
          </mesh>
        </geometry>
      </visual>
    </link>
    <joint name='LF_HAA' type='revolute'>
      <pose relative_to='base'>0.277 0.116 0 0 -0 0</pose>
      <parent>base</parent>
      <child>LF_HIP</child>
      <axis>
        <xyz>1 0 0</xyz>
        <limit>
          <lower>-9.42</lower>
          <upper>9.42</upper>
          <effort>80</effort>
          <velocity>15</velocity>
        </limit>
        <dynamics>
          <damping>0</damping>
          <friction>0</friction>
          <spring_reference>0</spring_reference>
          <spring_stiffness>0</spring_stiffness>
        </dynamics>
      </axis>
    </joint>
    <link name='LF_HIP'>
      <pose relative_to='LF_HAA'>0 0 0 0 -0 0</pose>
      <inertial>
        <pose>0.064516 -0.003787 -0.000152 0 -0 0</pose>
        <mass>1.42462</mass>
        <inertia>
          <ixx>0.00243023</ixx>
          <ixy>-1.53024e-05</ixy>
          <ixz>-2.18191e-05</ixz>
          <iyy>0.00230257</iyy>
          <iyz>2.6473e-05</iyz>
          <izz>0.00198068</izz>
        </inertia>
      </inertial>
      <collision name='LF_HIP_collision'>
        <pose>0.0635 -0.009 0 1.5708 -0 0</pose>
        <geometry>
          <cylinder>
            <length>0.1</length>
            <radius>0.08</radius>
          </cylinder>
        </geometry>
      </collision>
      <collision name='LF_HIP_collision_1'>
        <pose>0.0635 -0.074 0 1.5708 -0 0</pose>
        <geometry>
          <cylinder>
            <length>0.03</length>
            <radius>0.045</radius>
          </cylinder>
        </geometry>
      </collision>
      <visual name='LF_HIP_visual'>
        <pose>0 0 0 0 -0 0</pose>
        <geometry>
          <mesh>
            <scale>0.001 0.001 0.001</scale>
            <uri>model://anymal_b_simple_description/meshes/anymal_hip_l.dae</uri>
          </mesh>
        </geometry>
      </visual>
    </link>
    <joint name='LF_HFE' type='revolute'>
      <pose relative_to='LF_HIP'>0.0635 0.041 0 0 -0 0</pose>
      <parent>LF_HIP</parent>
      <child>LF_THIGH</child>
      <axis>
        <xyz>0 1 0</xyz>
        <limit>
          <lower>-9.42</lower>
          <upper>9.42</upper>
          <effort>80</effort>
          <velocity>15</velocity>
        </limit>
        <dynamics>
          <damping>0</damping>
          <friction>0</friction>
          <spring_reference>0</spring_reference>
          <spring_stiffness>0</spring_stiffness>
        </dynamics>
      </axis>
    </joint>
    <link name='LF_THIGH'>
      <pose relative_to='LF_HFE'>0 0 0 0 -0 0</pose>
      <inertial>
        <pose>-0.003898 0.054227 -0.214583 0 -0 0</pose>
        <mass>1.63498</mass>
        <inertia>
          <ixx>0.0120368</ixx>
          <ixy>6.76207e-05</ixy>
          <ixz>0.000287806</ixz>
          <iyy>0.0120644</iyy>
          <iyz>-0.0014061</iyz>
          <izz>0.00249423</izz>
        </inertia>
      </inertial>
      <collision name='LF_THIGH_collision'>
        <pose>0 0.035 -0.125 0.145 -0 0</pose>
        <geometry>
          <box>
            <size>0.08 0.04 0.25</size>
          </box>
        </geometry>
      </collision>
      <collision name='LF_THIGH_collision_1'>
        <pose>0 0.069 -0.25 1.5708 -0 0</pose>
        <geometry>
          <cylinder>
            <length>0.12</length>
            <radius>0.06</radius>
          </cylinder>
        </geometry>
      </collision>
      <collision name='LF_THIGH_collision_2'>
        <pose>0 -0.005 0 1.7158 -0 0</pose>
        <geometry>
          <cylinder>
            <length>0.12</length>
            <radius>0.066</radius>
          </cylinder>
        </geometry>
      </collision>
      <visual name='LF_THIGH_visual'>
        <pose>0 0 0 0 -0 0</pose>
        <geometry>
          <mesh>
            <scale>0.001 0.001 0.001</scale>
            <uri>model://anymal_b_simple_description/meshes/anymal_thigh_l.dae</uri>
          </mesh>
        </geometry>
      </visual>
    </link>
    <joint name='LF_KFE' type='revolute'>
      <pose relative_to='LF_THIGH'>0 0.109 -0.25 0 -0 0</pose>
      <parent>LF_THIGH</parent>
      <child>LF_SHANK</child>
      <axis>
        <xyz>0 1 0</xyz>
        <limit>
          <lower>-9.42</lower>
          <upper>9.42</upper>
          <effort>80</effort>
          <velocity>15</velocity>
        </limit>
        <dynamics>
          <damping>0</damping>
          <friction>0</friction>
          <spring_reference>0</spring_reference>
          <spring_stiffness>0</spring_stiffness>
        </dynamics>
      </axis>
    </joint>
    <link name='LF_SHANK'>
      <pose relative_to='LF_KFE'>0 0 0 0 -0 0</pose>
      <inertial>
        <pose>0.058733 -0.010824 -0.098064 0 -0 0</pose>
        <mass>0.347375</mass>
        <inertia>
          <ixx>0.00685813</ixx>
          <ixy>3.2229e-05</ixy>
          <ixz>0.00142869</ixz>
          <iyy>0.00770431</iyy>
          <iyz>-0.000316237</iyz>
          <izz>0.00101942</izz>
        </inertia>
      </inertial>
      <collision name='LF_SHANK_collision'>
        <pose>0.065 -0.015 0.01 0 1.5708 0</pose>
        <geometry>
          <box>
            <size>0.08 0.07 0.13</size>
          </box>
        </geometry>
      </collision>
      <collision name='LF_SHANK_fixed_joint_lump__LF_ADAPTER_collision_1'>
        <pose>0.1 -0.02 -0.160625 0 -0 0</pose>
        <geometry>
          <cylinder>
            <length>0.32125</length>
            <radius>0.015</radius>
          </cylinder>
        </geometry>
      </collision>
      <collision name='LF_SHANK_fixed_joint_lump__LF_COLLISION_collision_2'>
        <pose>0.1 -0.02 -0.298 0 -0 0</pose>
        <geometry>
          <sphere>
            <radius>0.031</radius>
          </sphere>
        </geometry>
      </collision>
      <visual name='LF_SHANK_visual'>
        <pose>0 0 0 0 -0 0</pose>
        <geometry>
          <mesh>
            <scale>0.001 0.001 0.001</scale>
            <uri>model://anymal_b_simple_description/meshes/anymal_shank_l.dae</uri>
          </mesh>
        </geometry>
      </visual>
      <visual name='LF_SHANK_fixed_joint_lump__LF_ADAPTER_visual_1'>
        <pose>0.1 -0.02 0.032 0 -0 0</pose>
        <geometry>
          <mesh>
            <scale>0.001 0.001 0.001</scale>
            <uri>model://anymal_b_simple_description/meshes/anymal_foot.dae</uri>
          </mesh>
        </geometry>
      </visual>
    </link>
    <joint name='LH_HAA' type='revolute'>
      <pose relative_to='base'>-0.277 0.116 0 0 -0 0</pose>
      <parent>base</parent>
      <child>LH_HIP</child>
      <axis>
        <xyz>1 0 0</xyz>
        <limit>
          <lower>-9.42</lower>
          <upper>9.42</upper>
          <effort>80</effort>
          <velocity>15</velocity>
        </limit>
        <dynamics>
          <damping>0</damping>
          <friction>0</friction>
          <spring_reference>0</spring_reference>
          <spring_stiffness>0</spring_stiffness>
        </dynamics>
      </axis>
    </joint>
    <link name='LH_HIP'>
      <pose relative_to='LH_HAA'>0 0 0 0 -0 0</pose>
      <inertial>
        <pose>-0.064516 -0.003787 -0.000152 0 -0 0</pose>
        <mass>1.42462</mass>
        <inertia>
          <ixx>0.00243023</ixx>
          <ixy>1.53024e-05</ixy>
          <ixz>2.18191e-05</ixz>
          <iyy>0.00230257</iyy>
          <iyz>2.6473e-05</iyz>
          <izz>0.00198068</izz>
        </inertia>
      </inertial>
      <collision name='LH_HIP_collision'>
        <pose>-0.0635 -0.009 0 -1.5708 0 0</pose>
        <geometry>
          <cylinder>
            <length>0.1</length>
            <radius>0.08</radius>
          </cylinder>
        </geometry>
      </collision>
      <collision name='LH_HIP_collision_1'>
        <pose>-0.0635 -0.074 0 -1.5708 0 0</pose>
        <geometry>
          <cylinder>
            <length>0.03</length>
            <radius>0.045</radius>
          </cylinder>
        </geometry>
      </collision>
      <visual name='LH_HIP_visual'>
        <pose>0 0 0 0 -0 3.14159</pose>
        <geometry>
          <mesh>
            <scale>0.001 0.001 0.001</scale>
            <uri>model://anymal_b_simple_description/meshes/anymal_hip_r.dae</uri>
          </mesh>
        </geometry>
      </visual>
    </link>
    <joint name='LH_HFE' type='revolute'>
      <pose relative_to='LH_HIP'>-0.0635 0.041 0 0 -0 0</pose>
      <parent>LH_HIP</parent>
      <child>LH_THIGH</child>
      <axis>
        <xyz>0 1 0</xyz>
        <limit>
          <lower>-9.42</lower>
          <upper>9.42</upper>
          <effort>80</effort>
          <velocity>15</velocity>
        </limit>
        <dynamics>
          <damping>0</damping>
          <friction>0</friction>
          <spring_reference>0</spring_reference>
          <spring_stiffness>0</spring_stiffness>
        </dynamics>
      </axis>
    </joint>
    <link name='LH_THIGH'>
      <pose relative_to='LH_HFE'>0 0 0 0 -0 0</pose>
      <inertial>
        <pose>0.003898 0.054227 -0.214583 0 -0 0</pose>
        <mass>1.63498</mass>
        <inertia>
          <ixx>0.0120368</ixx>
          <ixy>-6.76207e-05</ixy>
          <ixz>-0.000287806</ixz>
          <iyy>0.0120644</iyy>
          <iyz>-0.0014061</iyz>
          <izz>0.00249423</izz>
        </inertia>
      </inertial>
      <collision name='LH_THIGH_collision'>
        <pose>0 0.035 -0.125 0.145 -0 0</pose>
        <geometry>
          <box>
            <size>0.08 0.04 0.25</size>
          </box>
        </geometry>
      </collision>
      <collision name='LH_THIGH_collision_1'>
        <pose>0 0.069 -0.25 1.5708 -0 0</pose>
        <geometry>
          <cylinder>
            <length>0.12</length>
            <radius>0.06</radius>
          </cylinder>
        </geometry>
      </collision>
      <collision name='LH_THIGH_collision_2'>
        <pose>0 -0.005 0 1.7158 -0 0</pose>
        <geometry>
          <cylinder>
            <length>0.12</length>
            <radius>0.066</radius>
          </cylinder>
        </geometry>
      </collision>
      <visual name='LH_THIGH_visual'>
        <pose>0 0 0 0 -0 3.14159</pose>
        <geometry>
          <mesh>
            <scale>0.001 0.001 0.001</scale>
            <uri>model://anymal_b_simple_description/meshes/anymal_thigh_r.dae</uri>
          </mesh>
        </geometry>
      </visual>
    </link>
    <joint name='LH_KFE' type='revolute'>
      <pose relative_to='LH_THIGH'>0 0.109 -0.25 0 -0 0</pose>
      <parent>LH_THIGH</parent>
      <child>LH_SHANK</child>
      <axis>
        <xyz>0 1 0</xyz>
        <limit>
          <lower>-9.42</lower>
          <upper>9.42</upper>
          <effort>80</effort>
          <velocity>15</velocity>
        </limit>
        <dynamics>
          <damping>0</damping>
          <friction>0</friction>
          <spring_reference>0</spring_reference>
          <spring_stiffness>0</spring_stiffness>
        </dynamics>
      </axis>
    </joint>
    <link name='LH_SHANK'>
      <pose relative_to='LH_KFE'>0 0 0 0 -0 0</pose>
      <inertial>
        <pose>-0.058733 -0.010824 -0.098064 0 -0 0</pose>
        <mass>0.347375</mass>
        <inertia>
          <ixx>0.00685813</ixx>
          <ixy>-3.2229e-05</ixy>
          <ixz>-0.00142869</ixz>
          <iyy>0.00770431</iyy>
          <iyz>-0.000316237</iyz>
          <izz>0.00101942</izz>
        </inertia>
      </inertial>
      <collision name='LH_SHANK_collision'>
        <pose>-0.065 -0.015 0.01 0 1.5708 0</pose>
        <geometry>
          <box>
            <size>0.08 0.07 0.13</size>
          </box>
        </geometry>
      </collision>
      <collision name='LH_SHANK_fixed_joint_lump__LH_ADAPTER_collision_1'>
        <pose>-0.1 -0.02 -0.160625 0 -0 0</pose>
        <geometry>
          <cylinder>
            <length>0.32125</length>
            <radius>0.015</radius>
          </cylinder>
        </geometry>
      </collision>
      <collision name='LH_SHANK_fixed_joint_lump__LH_FOOT_collision_2'>
        <pose>-0.1 -0.02 -0.298 0 -0 0</pose>
        <geometry>
          <sphere>
            <radius>0.031</radius>
          </sphere>
        </geometry>
        <surface>
          <contact>
            <ode>
              <kp>1e+06</kp>
              <kd>100</kd>
            </ode>
          </contact>
          <friction>
            <ode>
              <mu>0.8</mu>
              <mu2>0.8</mu2>
            </ode>
          </friction>
        </surface>
      </collision>
      <visual name='LH_SHANK_visual'>
        <pose>0 0 0 0 -0 3.14159</pose>
        <geometry>
          <mesh>
            <scale>0.001 0.001 0.001</scale>
            <uri>model://anymal_b_simple_description/meshes/anymal_shank_r.dae</uri>
          </mesh>
        </geometry>
      </visual>
      <visual name='LH_SHANK_fixed_joint_lump__LH_ADAPTER_visual_1'>
        <pose>-0.1 -0.02 0.032 0 -0 3.14159</pose>
        <geometry>
          <mesh>
            <scale>0.001 0.001 0.001</scale>
            <uri>model://anymal_b_simple_description/meshes/anymal_foot.dae</uri>
          </mesh>
        </geometry>
      </visual>
    </link>
    <joint name='RF_HAA' type='revolute'>
      <pose relative_to='base'>0.277 -0.116 0 0 -0 0</pose>
      <parent>base</parent>
      <child>RF_HIP</child>
      <axis>
        <xyz>1 0 0</xyz>
        <limit>
          <lower>-9.42</lower>
          <upper>9.42</upper>
          <effort>80</effort>
          <velocity>15</velocity>
        </limit>
        <dynamics>
          <damping>0</damping>
          <friction>0</friction>
          <spring_reference>0</spring_reference>
          <spring_stiffness>0</spring_stiffness>
        </dynamics>
      </axis>
    </joint>
    <link name='RF_HIP'>
      <pose relative_to='RF_HAA'>0 0 0 0 -0 0</pose>
      <inertial>
        <pose>0.064516 0.003787 -0.000152 0 -0 0</pose>
        <mass>1.42462</mass>
        <inertia>
          <ixx>0.00243023</ixx>
          <ixy>1.53024e-05</ixy>
          <ixz>-2.18191e-05</ixz>
          <iyy>0.00230257</iyy>
          <iyz>-2.6473e-05</iyz>
          <izz>0.00198068</izz>
        </inertia>
      </inertial>
      <collision name='RF_HIP_collision'>
        <pose>0.0635 0.009 0 1.5708 -0 0</pose>
        <geometry>
          <cylinder>
            <length>0.1</length>
            <radius>0.08</radius>
          </cylinder>
        </geometry>
      </collision>
      <collision name='RF_HIP_collision_1'>
        <pose>0.0635 0.074 0 1.5708 -0 0</pose>
        <geometry>
          <cylinder>
            <length>0.03</length>
            <radius>0.045</radius>
          </cylinder>
        </geometry>
      </collision>
      <visual name='RF_HIP_visual'>
        <pose>0 0 0 0 -0 0</pose>
        <geometry>
          <mesh>
            <scale>0.001 0.001 0.001</scale>
            <uri>model://anymal_b_simple_description/meshes/anymal_hip_r.dae</uri>
          </mesh>
        </geometry>
      </visual>
    </link>
    <joint name='RF_HFE' type='revolute'>
      <pose relative_to='RF_HIP'>0.0635 -0.041 0 0 -0 0</pose>
      <parent>RF_HIP</parent>
      <child>RF_THIGH</child>
      <axis>
        <xyz>0 1 0</xyz>
        <limit>
          <lower>-9.42</lower>
          <upper>9.42</upper>
          <effort>80</effort>
          <velocity>15</velocity>
        </limit>
        <dynamics>
          <damping>0</damping>
          <friction>0</friction>
          <spring_reference>0</spring_reference>
          <spring_stiffness>0</spring_stiffness>
        </dynamics>
      </axis>
    </joint>
    <link name='RF_THIGH'>
      <pose relative_to='RF_HFE'>0 0 0 0 -0 0</pose>
      <inertial>
        <pose>-0.003898 -0.054227 -0.214583 0 -0 0</pose>
        <mass>1.63498</mass>
        <inertia>
          <ixx>0.0120368</ixx>
          <ixy>-6.76207e-05</ixy>
          <ixz>0.000287806</ixz>
          <iyy>0.0120644</iyy>
          <iyz>0.0014061</iyz>
          <izz>0.00249423</izz>
        </inertia>
      </inertial>
      <collision name='RF_THIGH_collision'>
        <pose>0 -0.035 -0.125 -0.145 0 0</pose>
        <geometry>
          <box>
            <size>0.08 0.04 0.25</size>
          </box>
        </geometry>
      </collision>
      <collision name='RF_THIGH_collision_1'>
        <pose>0 -0.069 -0.25 1.5708 -0 0</pose>
        <geometry>
          <cylinder>
            <length>0.12</length>
            <radius>0.06</radius>
          </cylinder>
        </geometry>
      </collision>
      <collision name='RF_THIGH_collision_2'>
        <pose>0 0.005 0 -1.7158 0 0</pose>
        <geometry>
          <cylinder>
            <length>0.12</length>
            <radius>0.066</radius>
          </cylinder>
        </geometry>
      </collision>
      <visual name='RF_THIGH_visual'>
        <pose>0 0 0 0 -0 0</pose>
        <geometry>
          <mesh>
            <scale>0.001 0.001 0.001</scale>
            <uri>model://anymal_b_simple_description/meshes/anymal_thigh_r.dae</uri>
          </mesh>
        </geometry>
      </visual>
    </link>
    <joint name='RF_KFE' type='revolute'>
      <pose relative_to='RF_THIGH'>0 -0.109 -0.25 0 -0 0</pose>
      <parent>RF_THIGH</parent>
      <child>RF_SHANK</child>
      <axis>
        <xyz>0 1 0</xyz>
        <limit>
          <lower>-9.42</lower>
          <upper>9.42</upper>
          <effort>80</effort>
          <velocity>15</velocity>
        </limit>
        <dynamics>
          <damping>0</damping>
          <friction>0</friction>
          <spring_reference>0</spring_reference>
          <spring_stiffness>0</spring_stiffness>
        </dynamics>
      </axis>
    </joint>
    <link name='RF_SHANK'>
      <pose relative_to='RF_KFE'>0 0 0 0 -0 0</pose>
      <inertial>
        <pose>0.058733 0.010824 -0.098064 0 -0 0</pose>
        <mass>0.347375</mass>
        <inertia>
          <ixx>0.00685813</ixx>
          <ixy>-3.2229e-05</ixy>
          <ixz>0.00142869</ixz>
          <iyy>0.00770431</iyy>
          <iyz>0.000316237</iyz>
          <izz>0.00101942</izz>
        </inertia>
      </inertial>
      <collision name='RF_SHANK_collision'>
        <pose>0.065 0.015 0.01 0 1.5708 0</pose>
        <geometry>
          <box>
            <size>0.08 0.07 0.13</size>
          </box>
        </geometry>
      </collision>
      <collision name='RF_SHANK_fixed_joint_lump__RF_ADAPTER_collision_1'>
        <pose>0.1 0.02 -0.160625 0 -0 0</pose>
        <geometry>
          <cylinder>
            <length>0.32125</length>
            <radius>0.015</radius>
          </cylinder>
        </geometry>
      </collision>
      <collision name='RF_SHANK_fixed_joint_lump__RF_FOOT_collision_2'>
        <pose>0.1 0.02 -0.298 0 -0 0</pose>
        <geometry>
          <sphere>
            <radius>0.031</radius>
          </sphere>
        </geometry>
        <surface>
          <contact>
            <ode>
              <kp>1e+06</kp>
              <kd>100</kd>
            </ode>
          </contact>
          <friction>
            <ode>
              <mu>0.8</mu>
              <mu2>0.8</mu2>
            </ode>
          </friction>
        </surface>
      </collision>
      <visual name='RF_SHANK_visual'>
        <pose>0 0 0 0 -0 0</pose>
        <geometry>
          <mesh>
            <scale>0.001 0.001 0.001</scale>
            <uri>model://anymal_b_simple_description/meshes/anymal_shank_r.dae</uri>
          </mesh>
        </geometry>
      </visual>
      <visual name='RF_SHANK_fixed_joint_lump__RF_ADAPTER_visual_1'>
        <pose>0.1 0.02 0.032 0 -0 0</pose>
        <geometry>
          <mesh>
            <scale>0.001 0.001 0.001</scale>
            <uri>model://anymal_b_simple_description/meshes/anymal_foot.dae</uri>
          </mesh>
        </geometry>
      </visual>
    </link>
    <joint name='RH_HAA' type='revolute'>
      <pose relative_to='base'>-0.277 -0.116 0 0 -0 0</pose>
      <parent>base</parent>
      <child>RH_HIP</child>
      <axis>
        <xyz>1 0 0</xyz>
        <limit>
          <lower>-9.42</lower>
          <upper>9.42</upper>
          <effort>80</effort>
          <velocity>15</velocity>
        </limit>
        <dynamics>
          <damping>0</damping>
          <friction>0</friction>
          <spring_reference>0</spring_reference>
          <spring_stiffness>0</spring_stiffness>
        </dynamics>
      </axis>
    </joint>
    <link name='RH_HIP'>
      <pose relative_to='RH_HAA'>0 0 0 0 -0 0</pose>
      <inertial>
        <pose>-0.064516 0.003787 -0.000152 0 -0 0</pose>
        <mass>1.42462</mass>
        <inertia>
          <ixx>0.00243023</ixx>
          <ixy>-1.53024e-05</ixy>
          <ixz>2.18191e-05</ixz>
          <iyy>0.00230257</iyy>
          <iyz>-2.6473e-05</iyz>
          <izz>0.00198068</izz>
        </inertia>
      </inertial>
      <collision name='RH_HIP_collision'>
        <pose>-0.0635 0.009 0 -1.5708 0 0</pose>
        <geometry>
          <cylinder>
            <length>0.1</length>
            <radius>0.08</radius>
          </cylinder>
        </geometry>
      </collision>
      <collision name='RH_HIP_collision_1'>
        <pose>-0.0635 0.074 0 -1.5708 0 0</pose>
        <geometry>
          <cylinder>
            <length>0.03</length>
            <radius>0.045</radius>
          </cylinder>
        </geometry>
      </collision>
      <visual name='RH_HIP_visual'>
        <pose>0 0 0 0 -0 3.14159</pose>
        <geometry>
          <mesh>
            <scale>0.001 0.001 0.001</scale>
            <uri>model://anymal_b_simple_description/meshes/anymal_hip_l.dae</uri>
          </mesh>
        </geometry>
      </visual>
    </link>
    <joint name='RH_HFE' type='revolute'>
      <pose relative_to='RH_HIP'>-0.0635 -0.041 0 0 -0 0</pose>
      <parent>RH_HIP</parent>
      <child>RH_THIGH</child>
      <axis>
        <xyz>0 1 0</xyz>
        <limit>
          <lower>-9.42</lower>
          <upper>9.42</upper>
          <effort>80</effort>
          <velocity>15</velocity>
        </limit>
        <dynamics>
          <damping>0</damping>
          <friction>0</friction>
          <spring_reference>0</spring_reference>
          <spring_stiffness>0</spring_stiffness>
        </dynamics>
      </axis>
    </joint>
    <link name='RH_THIGH'>
      <pose relative_to='RH_HFE'>0 0 0 0 -0 0</pose>
      <inertial>
        <pose>0.003898 -0.054227 -0.214583 0 -0 0</pose>
        <mass>1.63498</mass>
        <inertia>
          <ixx>0.0120368</ixx>
          <ixy>6.76207e-05</ixy>
          <ixz>-0.000287806</ixz>
          <iyy>0.0120644</iyy>
          <iyz>0.0014061</iyz>
          <izz>0.00249423</izz>
        </inertia>
      </inertial>
      <collision name='RH_THIGH_collision'>
        <pose>0 -0.035 -0.125 -0.145 0 0</pose>
        <geometry>
          <box>
            <size>0.08 0.04 0.25</size>
          </box>
        </geometry>
      </collision>
      <collision name='RH_THIGH_collision_1'>
        <pose>0 -0.069 -0.25 1.5708 -0 0</pose>
        <geometry>
          <cylinder>
            <length>0.12</length>
            <radius>0.06</radius>
          </cylinder>
        </geometry>
      </collision>
      <collision name='RH_THIGH_collision_2'>
        <pose>0 0.005 0 -1.7158 0 0</pose>
        <geometry>
          <cylinder>
            <length>0.12</length>
            <radius>0.066</radius>
          </cylinder>
        </geometry>
      </collision>
      <visual name='RH_THIGH_visual'>
        <pose>0 0 0 0 -0 3.14159</pose>
        <geometry>
          <mesh>
            <scale>0.001 0.001 0.001</scale>
            <uri>model://anymal_b_simple_description/meshes/anymal_thigh_l.dae</uri>
          </mesh>
        </geometry>
      </visual>
    </link>
    <joint name='RH_KFE' type='revolute'>
      <pose relative_to='RH_THIGH'>0 -0.109 -0.25 0 -0 0</pose>
      <parent>RH_THIGH</parent>
      <child>RH_SHANK</child>
      <axis>
        <xyz>0 1 0</xyz>
        <limit>
          <lower>-9.42</lower>
          <upper>9.42</upper>
          <effort>80</effort>
          <velocity>15</velocity>
        </limit>
        <dynamics>
          <damping>0</damping>
          <friction>0</friction>
          <spring_reference>0</spring_reference>
          <spring_stiffness>0</spring_stiffness>
        </dynamics>
      </axis>
    </joint>
    <link name='RH_SHANK'>
      <pose relative_to='RH_KFE'>0 0 0 0 -0 0</pose>
      <inertial>
        <pose>-0.058733 0.010824 -0.098064 0 -0 0</pose>
        <mass>0.347375</mass>
        <inertia>
          <ixx>0.00685813</ixx>
          <ixy>3.2229e-05</ixy>
          <ixz>-0.00142869</ixz>
          <iyy>0.00770431</iyy>
          <iyz>0.000316237</iyz>
          <izz>0.00101942</izz>
        </inertia>
      </inertial>
      <collision name='RH_SHANK_collision'>
        <pose>-0.065 0.015 0.01 0 1.5708 0</pose>
        <geometry>
          <box>
            <size>0.08 0.07 0.13</size>
          </box>
        </geometry>
      </collision>
      <collision name='RH_SHANK_fixed_joint_lump__RH_ADAPTER_collision_1'>
        <pose>-0.1 0.02 -0.160625 0 -0 0</pose>
        <geometry>
          <cylinder>
            <length>0.32125</length>
            <radius>0.015</radius>
          </cylinder>
        </geometry>
      </collision>
      <collision name='RH_SHANK_fixed_joint_lump__RH_FOOT_collision_2'>
        <pose>-0.1 0.02 -0.298 0 -0 0</pose>
        <geometry>
          <sphere>
            <radius>0.031</radius>
          </sphere>
        </geometry>
        <surface>
          <contact>
            <ode>
              <kp>1e+06</kp>
              <kd>100</kd>
            </ode>
          </contact>
          <friction>
            <ode>
              <mu>0.8</mu>
              <mu2>0.8</mu2>
            </ode>
          </friction>
        </surface>
      </collision>
      <visual name='RH_SHANK_visual'>
        <pose>0 0 0 0 -0 3.14159</pose>
        <geometry>
          <mesh>
            <scale>0.001 0.001 0.001</scale>
            <uri>model://anymal_b_simple_description/meshes/anymal_shank_l.dae</uri>
          </mesh>
        </geometry>
      </visual>
      <visual name='RH_SHANK_fixed_joint_lump__RH_ADAPTER_visual_1'>
        <pose>-0.1 0.02 0.032 0 -0 3.14159</pose>
        <geometry>
          <mesh>
            <scale>0.001 0.001 0.001</scale>
            <uri>model://anymal_b_simple_description/meshes/anymal_foot.dae</uri>
          </mesh>
        </geometry>
      </visual>
    </link>
    <static>0</static>
    <plugin name='gazebo_ros_control' filename='libgazebo_ros_control.so'>
      <legacyModeNS>1</legacyModeNS>
    </plugin>
  </model>
</sdf>
